cpp/tests/test_20240229172531.in
1000
0-999 o
0 B 1 NFLX 2705 30
0 S 2 NFLX 3260 1
0 C 1
0 S 3 AMD 2701 25
0 B 4 GOOGL 3290 10
0 C 2
1 B 5 MSFT 2705 30
1 S 6 INTC 3260 1
1 C 5
1 S 7 TSLA 2701 25
1 B 8 AMZN 3290 10
1 C 6
2 B 9 INTC 2705 30
2 S 10 GOOGL 3260 1
2 C 9
2 S 11 AAPL 2701 25
2 B 12 GOOGL 3290 10
2 C 10
3 B 13 INTC 2705 30
3 S 14 MSFT 3260 1
3 C 13
3 S 15 AAPL 2701 25
3 B 16 TSLA 3290 10
3 C 14
4 B 17 AMD 2705 30
4 S 18 AMD 3260 1
4 C 17
4 S 19 NVDA 2701 25
4 B 20 NFLX 3290 10
4 C 18
5 B 21 META 2705 30
5 S 22 AMD 3260 1
5 C 21
5 S 23 NVDA 2701 25
5 B 24 AMD 3290 10
5 C 22
6 B 25 AAPL 2705 30
6 S 26 NVDA 3260 1
6 C 25
6 S 27 AAPL 2701 25
6 B 28 AMZN 3290 10
6 C 26
7 B 29 META 2705 30
7 S 30 AMD 3260 1
7 C 29
7 S 31 NVDA 2701 25
7 B 32 INTC 3290 10
7 C 30
8 B 33 TSLA 2705 30
8 S 34 TSLA 3260 1
8 C 33
8 S 35 AMD 2701 25
8 B 36 GOOGL 3290 10
8 C 34
9 B 37 AMZN 2705 30
9 S 38 MSFT 3260 1
9 C 37
9 S 39 NFLX 2701 25
9 B 40 NVDA 3290 10
9 C 38
10 B 41 AMZN 2705 30
10 S 42 AMZN 3260 1
10 C 41
10 S 43 TSLA 2701 25
10 B 44 AMD 3290 10
10 C 42
11 B 45 TSLA 2705 30
11 S 46 AAPL 3260 1
11 C 45
11 S 47 INTC 2701 25
11 B 48 AMZN 3290 10
11 C 46
12 B 49 META 2705 30
12 S 50 GOOGL 3260 1
12 C 49
12 S 51 AMZN 2701 25
12 B 52 INTC 3290 10
12 C 50
13 B 53 MSFT 2705 30
13 S 54 AMZN 3260 1
13 C 53
13 S 55 INTC 2701 25
13 B 56 INTC 3290 10
13 C 54
14 B 57 AMD 2705 30
14 S 58 TSLA 3260 1
14 C 57
14 S 59 NVDA 2701 25
14 B 60 AAPL 3290 10
14 C 58
15 B 61 NVDA 2705 30
15 S 62 META 3260 1
15 C 61
15 S 63 MSFT 2701 25
15 B 64 NVDA 3290 10
15 C 62
16 B 65 MSFT 2705 30
16 S 66 MSFT 3260 1
16 C 65
16 S 67 META 2701 25
16 B 68 INTC 3290 10
16 C 66
17 B 69 MSFT 2705 30
17 S 70 AMD 3260 1
17 C 69
17 S 71 META 2701 25
17 B 72 AMZN 3290 10
17 C 70
18 B 73 NFLX 2705 30
18 S 74 AMD 3260 1
18 C 73
18 S 75 AMD 2701 25
18 B 76 NVDA 3290 10
18 C 74
19 B 77 AAPL 2705 30
19 S 78 NVDA 3260 1
19 C 77
19 S 79 NFLX 2701 25
19 B 80 GOOGL 3290 10
19 C 78
20 B 81 MSFT 2705 30
20 S 82 AMZN 3260 1
20 C 81
20 S 83 META 2701 25
20 B 84 AMZN 3290 10
20 C 82
21 B 85 META 2705 30
21 S 86 TSLA 3260 1
21 C 85
21 S 87 GOOGL 2701 25
21 B 88 INTC 3290 10
21 C 86
22 B 89 MSFT 2705 30
22 S 90 NFLX 3260 1
22 C 89
22 S 91 INTC 2701 25
22 B 92 AMD 3290 10
22 C 90
23 B 93 AAPL 2705 30
23 S 94 GOOGL 3260 1
23 C 93
23 S 95 MSFT 2701 25
23 B 96 AAPL 3290 10
23 C 94
24 B 97 NFLX 2705 30
24 S 98 AMZN 3260 1
24 C 97
24 S 99 NFLX 2701 25
24 B 100 TSLA 3290 10
24 C 98
25 B 101 AMZN 2705 30
25 S 102 NFLX 3260 1
25 C 101
25 S 103 TSLA 2701 25
25 B 104 AAPL 3290 10
25 C 102
26 B 105 NFLX 2705 30
26 S 106 AMZN 3260 1
26 C 105
26 S 107 NVDA 2701 25
26 B 108 NVDA 3290 10
26 C 106
27 B 109 TSLA 2705 30
27 S 110 AMZN 3260 1
27 C 109
27 S 111 TSLA 2701 25
27 B 112 GOOGL 3290 10
27 C 110
28 B 113 AAPL 2705 30
28 S 114 MSFT 3260 1
28 C 113
28 S 115 AAPL 2701 25
28 B 116 INTC 3290 10
28 C 114
29 B 117 META 2705 30
29 S 118 META 3260 1
29 C 117
29 S 119 NFLX 2701 25
29 B 120 META 3290 10
29 C 118
30 B 121 NVDA 2705 30
30 S 122 AMZN 3260 1
30 C 121
30 S 123 INTC 2701 25
30 B 124 TSLA 3290 10
30 C 122
31 B 125 NFLX 2705 30
31 S 126 AMZN 3260 1
31 C 125
31 S 127 AMZN 2701 25
31 B 128 AMD 3290 10
31 C 126
32 B 129 NFLX 2705 30
32 S 130 TSLA 3260 1
32 C 129
32 S 131 AAPL 2701 25
32 B 132 META 3290 10
32 C 130
33 B 133 META 2705 30
33 S 134 TSLA 3260 1
33 C 133
33 S 135 AAPL 2701 25
33 B 136 META 3290 10
33 C 134
34 B 137 NFLX 2705 30
34 S 138 NVDA 3260 1
34 C 137
34 S 139 AAPL 2701 25
34 B 140 AAPL 3290 10
34 C 138
35 B 141 NVDA 2705 30
35 S 142 AAPL 3260 1
35 C 141
35 S 143 TSLA 2701 25
35 B 144 NVDA 3290 10
35 C 142
36 B 145 META 2705 30
36 S 146 NVDA 3260 1
36 C 145
36 S 147 NVDA 2701 25
36 B 148 MSFT 3290 10
36 C 146
37 B 149 AMZN 2705 30
37 S 150 NVDA 3260 1
37 C 149
37 S 151 GOOGL 2701 25
37 B 152 AAPL 3290 10
37 C 150
38 B 153 AMZN 2705 30
38 S 154 AMZN 3260 1
38 C 153
38 S 155 GOOGL 2701 25
38 B 156 AMZN 3290 10
38 C 154
39 B 157 GOOGL 2705 30
39 S 158 AMZN 3260 1
39 C 157
39 S 159 AMD 2701 25
39 B 160 AMD 3290 10
39 C 158
40 B 161 AMD 2705 30
40 S 162 AMD 3260 1
40 C 161
40 S 163 AMZN 2701 25
40 B 164 META 3290 10
40 C 162
41 B 165 NVDA 2705 30
41 S 166 INTC 3260 1
41 C 165
41 S 167 INTC 2701 25
41 B 168 NVDA 3290 10
41 C 166
42 B 169 META 2705 30
42 S 170 INTC 3260 1
42 C 169
42 S 171 MSFT 2701 25
42 B 172 TSLA 3290 10
42 C 170
43 B 173 META 2705 30
43 S 174 MSFT 3260 1
43 C 173
43 S 175 INTC 2701 25
43 B 176 AMZN 3290 10
43 C 174
44 B 177 INTC 2705 30
44 S 178 AAPL 3260 1
44 C 177
44 S 179 AMD 2701 25
44 B 180 AAPL 3290 10
44 C 178
45 B 181 META 2705 30
45 S 182 MSFT 3260 1
45 C 181
45 S 183 META 2701 25
45 B 184 GOOGL 3290 10
45 C 182
46 B 185 NFLX 2705 30
46 S 186 GOOGL 3260 1
46 C 185
46 S 187 AMZN 2701 25
46 B 188 INTC 3290 10
46 C 186
47 B 189 AAPL 2705 30
47 S 190 INTC 3260 1
47 C 189
47 S 191 TSLA 2701 25
47 B 192 TSLA 3290 10
47 C 190
48 B 193 GOOGL 2705 30
48 S 194 MSFT 3260 1
48 C 193
48 S 195 TSLA 2701 25
48 B 196 INTC 3290 10
48 C 194
49 B 197 NFLX 2705 30
49 S 198 NVDA 3260 1
49 C 197
49 S 199 GOOGL 2701 25
49 B 200 TSLA 3290 10
49 C 198
50 B 201 AAPL 2705 30
50 S 202 GOOGL 3260 1
50 C 201
50 S 203 NFLX 2701 25
50 B 204 AMD 3290 10
50 C 202
51 B 205 AMZN 2705 30
51 S 206 MSFT 3260 1
51 C 205
51 S 207 AAPL 2701 25
51 B 208 AMZN 3290 10
51 C 206
52 B 209 MSFT 2705 30
52 S 210 TSLA 3260 1
52 C 209
52 S 211 META 2701 25
52 B 212 AMZN 3290 10
52 C 210
53 B 213 NFLX 2705 30
53 S 214 MSFT 3260 1
53 C 213
53 S 215 GOOGL 2701 25
53 B 216 AMZN 3290 10
53 C 214
54 B 217 MSFT 2705 30
54 S 218 TSLA 3260 1
54 C 217
54 S 219 INTC 2701 25
54 B 220 AMZN 3290 10
54 C 218
55 B 221 META 2705 30
55 S 222 INTC 3260 1
55 C 221
55 S 223 MSFT 2701 25
55 B 224 GOOGL 3290 10
55 C 222
56 B 225 NFLX 2705 30
56 S 226 AMZN 3260 1
56 C 225
56 S 227 INTC 2701 25
56 B 228 META 3290 10
56 C 226
57 B 229 NVDA 2705 30
57 S 230 TSLA 3260 1
57 C 229
57 S 231 META 2701 25
57 B 232 NFLX 3290 10
57 C 230
58 B 233 MSFT 2705 30
58 S 234 META 3260 1
58 C 233
58 S 235 AMD 2701 25
58 B 236 AMZN 3290 10
58 C 234
59 B 237 TSLA 2705 30
59 S 238 AMZN 3260 1
59 C 237
59 S 239 TSLA 2701 25
59 B 240 NFLX 3290 10
59 C 238
60 B 241 AAPL 2705 30
60 S 242 AAPL 3260 1
60 C 241
60 S 243 NVDA 2701 25
60 B 244 GOOGL 3290 10
60 C 242
61 B 245 AMZN 2705 30
61 S 246 META 3260 1
61 C 245
61 S 247 GOOGL 2701 25
61 B 248 INTC 3290 10
61 C 246
62 B 249 NVDA 2705 30
62 S 250 INTC 3260 1
62 C 249
62 S 251 NVDA 2701 25
62 B 252 INTC 3290 10
62 C 250
63 B 253 AAPL 2705 30
63 S 254 META 3260 1
63 C 253
63 S 255 INTC 2701 25
63 B 256 TSLA 3290 10
63 C 254
64 B 257 AMZN 2705 30
64 S 258 NVDA 3260 1
64 C 257
64 S 259 TSLA 2701 25
64 B 260 AMD 3290 10
64 C 258
65 B 261 AMZN 2705 30
65 S 262 NFLX 3260 1
65 C 261
65 S 263 AMZN 2701 25
65 B 264 NFLX 3290 10
65 C 262
66 B 265 AMZN 2705 30
66 S 266 NVDA 3260 1
66 C 265
66 S 267 NFLX 2701 25
66 B 268 INTC 3290 10
66 C 266
67 B 269 MSFT 2705 30
67 S 270 META 3260 1
67 C 269
67 S 271 MSFT 2701 25
67 B 272 TSLA 3290 10
67 C 270
68 B 273 MSFT 2705 30
68 S 274 META 3260 1
68 C 273
68 S 275 AMZN 2701 25
68 B 276 NFLX 3290 10
68 C 274
69 B 277 GOOGL 2705 30
69 S 278 MSFT 3260 1
69 C 277
69 S 279 AAPL 2701 25
69 B 280 AAPL 3290 10
69 C 278
70 B 281 AMD 2705 30
70 S 282 MSFT 3260 1
70 C 281
70 S 283 NVDA 2701 25
70 B 284 MSFT 3290 10
70 C 282
71 B 285 NFLX 2705 30
71 S 286 TSLA 3260 1
71 C 285
71 S 287 AMD 2701 25
71 B 288 AMZN 3290 10
71 C 286
72 B 289 NFLX 2705 30
72 S 290 AMZN 3260 1
72 C 289
72 S 291 META 2701 25
72 B 292 NVDA 3290 10
72 C 290
73 B 293 AAPL 2705 30
73 S 294 TSLA 3260 1
73 C 293
73 S 295 GOOGL 2701 25
73 B 296 AMD 3290 10
73 C 294
74 B 297 TSLA 2705 30
74 S 298 TSLA 3260 1
74 C 297
74 S 299 AMZN 2701 25
74 B 300 MSFT 3290 10
74 C 298
75 B 301 AMZN 2705 30
75 S 302 INTC 3260 1
75 C 301
75 S 303 NFLX 2701 25
75 B 304 NVDA 3290 10
75 C 302
76 B 305 MSFT 2705 30
76 S 306 NFLX 3260 1
76 C 305
76 S 307 GOOGL 2701 25
76 B 308 META 3290 10
76 C 306
77 B 309 META 2705 30
77 S 310 INTC 3260 1
77 C 309
77 S 311 AMD 2701 25
77 B 312 NFLX 3290 10
77 C 310
78 B 313 INTC 2705 30
78 S 314 MSFT 3260 1
